Traceback (most recent call last):
  File "/usr/local/lib/python3.9/dist-packages/jupyter_cache/executors/utils.py", line 58, in single_nb_execution
    executenb(
  File "/usr/local/lib/python3.9/dist-packages/nbclient/client.py", line 1204, in execute
    return NotebookClient(nb=nb, resources=resources, km=km, **kwargs).execute()
  File "/usr/local/lib/python3.9/dist-packages/nbclient/util.py", line 84, in wrapped
    return just_run(coro(*args, **kwargs))
  File "/usr/local/lib/python3.9/dist-packages/nbclient/util.py", line 62, in just_run
    return loop.run_until_complete(coro)
  File "/usr/lib/python3.9/asyncio/base_events.py", line 647, in run_until_complete
    return future.result()
  File "/usr/local/lib/python3.9/dist-packages/nbclient/client.py", line 663, in async_execute
    await self.async_execute_cell(
  File "/usr/local/lib/python3.9/dist-packages/nbclient/client.py", line 965, in async_execute_cell
    await self._check_raise_for_error(cell, cell_index, exec_reply)
  File "/usr/local/lib/python3.9/dist-packages/nbclient/client.py", line 862, in _check_raise_for_error
    raise CellExecutionError.from_cell_and_msg(cell, exec_reply_content)
nbclient.exceptions.CellExecutionError: An error occurred while executing the following cell:
------------------
conn = psycopg2.connect(database="prosain201", user="postgres", password="rifa", host="localhost", port="5432")
cur = conn.cursor()
cur.execute("SELECT sepallength FROM iris")
sl = cur.fetchall()
sl = pd.DataFrame(sl,columns=['Sepal Length'])
sl.head()
------------------

[0;31m[0m
[0;31mOperationalError[0mTraceback (most recent call last)
[0;32m<ipython-input-6-f082ad7ec146>[0m in [0;36m<module>[0;34m[0m
[0;32m----> 1[0;31m [0mconn[0m [0;34m=[0m [0mpsycopg2[0m[0;34m.[0m[0mconnect[0m[0;34m([0m[0mdatabase[0m[0;34m=[0m[0;34m"prosain201"[0m[0;34m,[0m [0muser[0m[0;34m=[0m[0;34m"postgres"[0m[0;34m,[0m [0mpassword[0m[0;34m=[0m[0;34m"rifa"[0m[0;34m,[0m [0mhost[0m[0;34m=[0m[0;34m"localhost"[0m[0;34m,[0m [0mport[0m[0;34m=[0m[0;34m"5432"[0m[0;34m)[0m[0;34m[0m[0;34m[0m[0m
[0m[1;32m      2[0m [0mcur[0m [0;34m=[0m [0mconn[0m[0;34m.[0m[0mcursor[0m[0;34m([0m[0;34m)[0m[0;34m[0m[0;34m[0m[0m
[1;32m      3[0m [0mcur[0m[0;34m.[0m[0mexecute[0m[0;34m([0m[0;34m"SELECT sepallength FROM iris"[0m[0;34m)[0m[0;34m[0m[0;34m[0m[0m
[1;32m      4[0m [0msl[0m [0;34m=[0m [0mcur[0m[0;34m.[0m[0mfetchall[0m[0;34m([0m[0;34m)[0m[0;34m[0m[0;34m[0m[0m
[1;32m      5[0m [0msl[0m [0;34m=[0m [0mpd[0m[0;34m.[0m[0mDataFrame[0m[0;34m([0m[0msl[0m[0;34m,[0m[0mcolumns[0m[0;34m=[0m[0;34m[[0m[0;34m'Sepal Length'[0m[0;34m][0m[0;34m)[0m[0;34m[0m[0;34m[0m[0m

[0;32m/usr/local/lib/python3.9/dist-packages/psycopg2/__init__.py[0m in [0;36mconnect[0;34m(dsn, connection_factory, cursor_factory, **kwargs)[0m
[1;32m    120[0m [0;34m[0m[0m
[1;32m    121[0m     [0mdsn[0m [0;34m=[0m [0m_ext[0m[0;34m.[0m[0mmake_dsn[0m[0;34m([0m[0mdsn[0m[0;34m,[0m [0;34m**[0m[0mkwargs[0m[0;34m)[0m[0;34m[0m[0;34m[0m[0m
[0;32m--> 122[0;31m     [0mconn[0m [0;34m=[0m [0m_connect[0m[0;34m([0m[0mdsn[0m[0;34m,[0m [0mconnection_factory[0m[0;34m=[0m[0mconnection_factory[0m[0;34m,[0m [0;34m**[0m[0mkwasync[0m[0;34m)[0m[0;34m[0m[0;34m[0m[0m
[0m[1;32m    123[0m     [0;32mif[0m [0mcursor_factory[0m [0;32mis[0m [0;32mnot[0m [0;32mNone[0m[0;34m:[0m[0;34m[0m[0;34m[0m[0m
[1;32m    124[0m         [0mconn[0m[0;34m.[0m[0mcursor_factory[0m [0;34m=[0m [0mcursor_factory[0m[0;34m[0m[0;34m[0m[0m

[0;31mOperationalError[0m: connection to server at "localhost" (127.0.0.1), port 5432 failed: Connection refused
	Is the server running on that host and accepting TCP/IP connections?
connection to server at "localhost" (::1), port 5432 failed: Cannot assign requested address
	Is the server running on that host and accepting TCP/IP connections?

OperationalError: connection to server at "localhost" (127.0.0.1), port 5432 failed: Connection refused
	Is the server running on that host and accepting TCP/IP connections?
connection to server at "localhost" (::1), port 5432 failed: Cannot assign requested address
	Is the server running on that host and accepting TCP/IP connections?


